<?xml version="1.0"?>
<robot name="robot" xmlns:xacro="http://www.ros.org/wiki/xacro">

  <xacro:property name="length_wheel" value="0.05"/>
  <xacro:property name="radius_wheel"  value="0.06"/>
  <xacro:property name="camera_link"   value="0.05"/>
  <xacro:property name="PI" value="3.1415926"/>

  <xacro:macro name="default_inertial" params="mass">
    <inertial>
      <mass value="${mass}"/>
      <inertia ixx="0.1" ixy="0.0" ixz="0.0"
               iyy="0.1" iyz="0.0" izz="0.1"/>
    </inertial>
  </xacro:macro>

  <!-- ===== 唯一改动：dummy 现在挂在 base_link 下 ===== -->
  <link name="dummy">
    <inertial>
      <mass value="1e-3"/>
      <inertia ixx="1e-6" ixy="0" ixz="0"
               iyy="1e-6" iyz="0" izz="1e-6"/>
    </inertial>
  </link>

  <joint name="dummy_joint" type="fixed">
    <parent link="base_link"/>
    <child  link="dummy"/>
    <origin xyz="0 0 0" rpy="0 0 0"/>
  </joint>
  <!-- =================================================== -->

  <link name="base_footprint">
    <visual>
      <geometry>
        <box size="0.001 0.001 0.001"/>
      </geometry>
      <origin rpy="0 0 0" xyz="0 0 0"/>
    </visual>
    <xacro:default_inertial mass="0.0001"/>
  </link>

  <joint name="base_footprint_joint" type="fixed">
    <origin xyz="0 0 0"/>
    <parent link="base_footprint"/>
    <child  link="base_link"/>
  </joint>

  <link name="base_link">
    <visual>
      <geometry>
        <box size="0.2 .3 .1"/>
      </geometry>
      <origin rpy="0 0 ${PI/2}" xyz="0 0 0.05"/>
      <material name="white">
        <color rgba="1 1 1 1"/>
      </material>
    </visual>
    <collision>
      <geometry>
        <box size="0.2 .3 0.1"/>
      </geometry>
    </collision>
    <xacro:default_inertial mass="8.2"/>
  </link>

  <!-- 四个轮子 -->
  <link name="wheel_1">
    <visual>
      <geometry>
        <cylinder length="${length_wheel}" radius="${radius_wheel}"/>
      </geometry>
      <origin rpy="0 0 0" xyz="0 0 0"/>
      <material name="black">
        <color rgba="0 0 0 1"/>
      </material>
    </visual>
    <collision>
      <geometry>
        <cylinder length="${length_wheel}" radius="${radius_wheel}"/>
      </geometry>
    </collision>
    <mu1>0.5</mu1>
    <mu2>0.5</mu2>
    <xacro:default_inertial mass="0.5"/>
  </link>

  <link name="wheel_2">
    <visual>
      <geometry>
        <cylinder length="${length_wheel}" radius="${radius_wheel}"/>
      </geometry>
      <origin rpy="0 0 0" xyz="0 0 0"/>
      <material name="black"/>
    </visual>
    <collision>
      <geometry>
        <cylinder length="${length_wheel}" radius="${radius_wheel}"/>
      </geometry>
    </collision>
    <mu1>0.5</mu1>
    <mu2>0.5</mu2>
    <xacro:default_inertial mass="0.5"/>
  </link>

  <link name="wheel_3">
    <visual>
      <geometry>
        <cylinder length="${length_wheel}" radius="${radius_wheel}"/>
      </geometry>
      <origin rpy="0 0 0" xyz="0 0 0"/>
      <material name="black"/>
    </visual>
    <collision>
      <geometry>
        <cylinder length="${length_wheel}" radius="${radius_wheel}"/>
      </geometry>
    </collision>
    <mu1>0.5</mu1>
    <mu2>0.5</mu2>
    <xacro:default_inertial mass="0.5"/>
  </link>

  <link name="wheel_4">
    <visual>
      <geometry>
        <cylinder length="${length_wheel}" radius="${radius_wheel}"/>
      </geometry>
      <origin rpy="0 0 0" xyz="0 0 0"/>
      <material name="black"/>
    </visual>
    <collision>
      <geometry>
        <cylinder length="${length_wheel}" radius="${radius_wheel}"/>
      </geometry>
    </collision>
    <mu1>0.5</mu1>
    <mu2>0.5</mu2>
    <xacro:default_inertial mass="0.5"/>
  </link>

  <joint name="base_to_wheel1" type="continuous">
    <parent link="base_link"/>
    <child  link="wheel_1"/>
    <origin rpy="${-PI/2} 0 0" xyz="0.1  0.13 0"/>
    <axis xyz="0 0 1"/>
  </joint>

  <joint name="base_to_wheel2" type="continuous">
    <axis xyz="0 0 1"/>
    <parent link="base_link"/>
    <child  link="wheel_2"/>
    <origin rpy="${-PI/2} 0 0" xyz="-0.1 0.13 0"/>
  </joint>

  <joint name="base_to_wheel3" type="continuous">
    <parent link="base_link"/>
    <child  link="wheel_3"/>
    <origin rpy="${-PI/2} 0 0" xyz="0.1 -0.13 0"/>
    <axis xyz="0 0 1"/>
  </joint>

  <joint name="base_to_wheel4" type="continuous">
    <parent link="base_link"/>
    <child  link="wheel_4"/>
    <origin rpy="${-PI/2} 0 0" xyz="-0.1 -0.13 0"/>
    <axis xyz="0 0 1"/>
  </joint>

  <!-- IMU -->
  <link name="imu_link">
    <collision>
      <origin xyz="0 0 0" rpy="0 0 0"/>
      <geometry>
        <box size="0.05 0.05 0.05"/>
      </geometry>
    </collision>
    <visual>
      <origin xyz="0 0 0" rpy="0 0 0"/>
      <geometry>
        <box size="0.05 0.05 0.05"/>
      </geometry>
      <material name="green">
        <color rgba="0 1 0 1"/>
      </material>
    </visual>
    <inertial>
      <mass value="1e-2"/>
      <origin xyz="0 0 0" rpy="0 0 0"/>
      <inertia ixx="1e-6" ixy="0" ixz="0" iyy="1e-6" iyz="0" izz="1e-6"/>
    </inertial>
  </link>

  <joint name="imu_joint" type="fixed">
    <axis xyz="0 1 0"/>
    <origin xyz="0.125 0 0.125" rpy="0 0 0"/>
    <parent link="base_link"/>
    <child  link="imu_link"/>
  </joint>

  <!-- Camera -->
  <link name="camera_link">
    <collision>
      <origin xyz="0 0 0" rpy="0 0 0"/>
      <geometry>
        <box size="0.05 0.05 0.05"/>
      </geometry>
    </collision>
    <visual>
      <origin xyz="0 0 0" rpy="0 0 0"/>
      <geometry>
        <box size="0.05 0.05 0.05"/>
      </geometry>
      <material name="red">
        <color rgba="1 0 0 1"/>
      </material>
    </visual>
    <inertial>
      <mass value="1e-2"/>
      <origin xyz="0 0 0" rpy="0 0 0"/>
      <inertia ixx="1e-6" ixy="0" ixz="0" iyy="1e-6" iyz="0" izz="1e-6"/>
    </inertial>
  </link>

  <joint name="camera_joint" type="fixed">
    <axis xyz="0 1 0"/>
    <origin xyz="0.125 0 0.175" rpy="0 0 0"/>
    <parent link="base_link"/>
    <child  link="camera_link"/>
  </joint>

  <!-- Hokuyo -->
  <link name="laser_frame">
    <collision>
      <origin xyz="0 0 0" rpy="0 0 0"/>
      <geometry>
        <box size="0.05 0.05 0.05"/>
      </geometry>
    </collision>
    <visual>
      <origin xyz="0 0 0" rpy="0 0 0"/>
      <geometry>
        <mesh filename="package://gazebo_pkg/meshes/hokuyo.dae"/>
      </geometry>
    </visual>
    <inertial>
      <mass value="1e-2"/>
      <origin xyz="0 0 0" rpy="0 0 0"/>
      <inertia ixx="1e-6" ixy="0" ixz="0" iyy="1e-6" iyz="0" izz="1e-6"/>
    </inertial>
  </link>

  <joint name="hokuyo_joint" type="fixed">
    <origin xyz="0.125 0.0 0.225" rpy="0 0 0"/>
    <parent link="base_link"/>
    <child  link="laser_frame"/>
  </joint>

  <!-- Gazebo 材料 -->
  <gazebo reference="base_link">
    <material>Gazebo/Orange</material>
  </gazebo>
  <gazebo reference="wheel_1">
    <material>Gazebo/Red</material>
  </gazebo>
  <gazebo reference="wheel_2">
    <material>Gazebo/Black</material>
  </gazebo>
  <gazebo reference="wheel_3">
    <material>Gazebo/Red</material>
  </gazebo>
  <gazebo reference="wheel_4">
    <material>Gazebo/Black</material>
  </gazebo>

  <!-- 激光传感器 -->
  <gazebo reference="laser_frame">
    <sensor type="ray" name="head_hokuyo_sensor">
      <pose>0 0 0 0 0 0</pose>
      <visualize>false</visualize>
      <update_rate>15</update_rate>
      <ray>
        <scan>
          <horizontal>
            <samples>720</samples>
            <resolution>1</resolution>
            <min_angle>-3.1415926</min_angle>
            <max_angle>3.1415926</max_angle>
          </horizontal>
        </scan>
        <range>
          <min>0.05</min>
          <max>30.0</max>
          <resolution>0.01</resolution>
        </range>
        <noise>
          <type>gaussian</type>
          <mean>0.0</mean>
          <stddev>0.01</stddev>
        </noise>
      </ray>
      <plugin name="gazebo_ros_head_hokuyo_controller" filename="libgazebo_ros_laser.so">
        <topicName>/scan</topicName>
        <frameName>laser_frame</frameName>
      </plugin>
    </sensor>
  </gazebo>

  <!-- 相机 -->
  <gazebo reference="camera_link">
    <sensor type="camera" name="camera1">
      <update_rate>30.0</update_rate>
      <camera name="head">
        <horizontal_fov>1.3962634</horizontal_fov>
        <image>
          <width>1920</width>
          <height>1080</height>
          <format>R8G8B8</format>
        </image>
        <clip>
          <near>0.02</near>
          <far>300</far>
        </clip>
        <noise>
          <type>gaussian</type>
          <mean>0.0</mean>
          <stddev>0.007</stddev>
        </noise>
      </camera>
      <plugin name="camera_controller" filename="libgazebo_ros_camera.so">
        <alwaysOn>true</alwaysOn>
        <updateRate>0.0</updateRate>
        <cameraName>/</cameraName>
        <imageTopicName>/cam</imageTopicName>
        <cameraInfoTopicName>camera_info</cameraInfoTopicName>
        <frameName>camera_link</frameName>
        <hackBaseline>0.07</hackBaseline>
        <distortionK1>0.0</distortionK1>
        <distortionK2>0.0</distortionK2>
        <distortionK3>0.0</distortionK3>
        <distortionT1>0.0</distortionT1>
        <distortionT2>0.0</distortionT2>
      </plugin>
    </sensor>
  </gazebo>

  <!-- 平面移动插件 -->
  <gazebo>
    <plugin name="planar_controller" filename="libgazebo_ros_planar_move.so">
      <enableYAxis>true</enableYAxis>
      <commandTopic>/cmd_vel</commandTopic>
      <odometryTopic>/odom</odometryTopic>
      <odometryFrame>odom</odometryFrame>
      <odometryRate>30</odometryRate>
      <robotBaseFrame>base_footprint</robotBaseFrame>
    </plugin>
  </gazebo>

  <!-- IMU 插件 -->
  <gazebo reference="imu_link">
    <material>Gazebo/Orange</material>
    <gravity>true</gravity>
    <sensor name="imu_sensor" type="imu">
      <always_on>true</always_on>
      <update_rate>100</update_rate>
      <visualize>true</visualize>
      <topic>__default_topic__</topic>
      <plugin filename="libgazebo_ros_imu_sensor.so" name="imu_plugin">
        <topicName>/imu</topicName>
        <bodyName>imu_link</bodyName>
        <updateRateHZ>100.0</updateRateHZ>
        <gaussianNoise>0.0</gaussianNoise>
        <xyzOffset>0 0 0</xyzOffset>
        <rpyOffset>0 0 0</rpyOffset>
        <frameName>imu_link</frameName>
      </plugin>
      <pose>0 0 0 0 0 0</pose>
    </sensor>
  </gazebo>

</robot>